package tryandcatch;

public class ExceptionDemo {
    public static void main(String[] args) {
        try {
            // Code that may cause an exception
            int numerator = 10;
            int denominator = 0;
            int result = numerator / denominator; // This will throw an ArithmeticException
            System.out.println("Result: " + result); // This line won't be reached
        } catch (ArithmeticException e) {
            // Catch and handle the exception
            System.err.println("An arithmetic exception occurred: " + e.getMessage());
        } finally {
            // This block will always be executed, whether there is an exception or not
            System.out.println("This is the finally block.");
        }

        // Rest of the program continues...
        System.out.println("Program continues after the exception handling.");
    }
}
